[2024-08-13T16:12:55.649+0000] {taskinstance.py:1956} INFO - Dependencies all met for dep_context=non-requeueable deps ti=<TaskInstance: create_new_data.create_new_data_task manual__2024-08-13T16:12:51.374142+00:00 [queued]>
[2024-08-13T16:12:55.660+0000] {taskinstance.py:1956} INFO - Dependencies all met for dep_context=requeueable deps ti=<TaskInstance: create_new_data.create_new_data_task manual__2024-08-13T16:12:51.374142+00:00 [queued]>
[2024-08-13T16:12:55.660+0000] {taskinstance.py:2170} INFO - Starting attempt 1 of 1
[2024-08-13T16:12:55.686+0000] {taskinstance.py:2191} INFO - Executing <Task(PythonOperator): create_new_data_task> on 2024-08-13 16:12:51.374142+00:00
[2024-08-13T16:12:55.693+0000] {standard_task_runner.py:60} INFO - Started process 851 to run task
[2024-08-13T16:12:55.698+0000] {standard_task_runner.py:87} INFO - Running: ['***', 'tasks', 'run', 'create_new_data', 'create_new_data_task', 'manual__2024-08-13T16:12:51.374142+00:00', '--job-id', '6', '--raw', '--subdir', 'DAGS_FOLDER/create_new_data.py', '--cfg-path', '/tmp/tmpk70bvqum']
[2024-08-13T16:12:55.700+0000] {standard_task_runner.py:88} INFO - Job 6: Subtask create_new_data_task
[2024-08-13T16:12:55.721+0000] {warnings.py:109} WARNING - /home/***/.local/lib/python3.8/site-packages/***/settings.py:194: DeprecationWarning: The sql_alchemy_conn option in [core] has been moved to the sql_alchemy_conn option in [database] - the old setting has been used, but please update your config.
  SQL_ALCHEMY_CONN = conf.get("database", "SQL_ALCHEMY_CONN")

[2024-08-13T16:12:55.776+0000] {task_command.py:423} INFO - Running <TaskInstance: create_new_data.create_new_data_task manual__2024-08-13T16:12:51.374142+00:00 [running]> on host 3be304d8e560
[2024-08-13T16:12:55.917+0000] {taskinstance.py:2480} INFO - Exporting env vars: AIRFLOW_CTX_DAG_OWNER='***' AIRFLOW_CTX_DAG_ID='create_new_data' AIRFLOW_CTX_TASK_ID='create_new_data_task' AIRFLOW_CTX_EXECUTION_DATE='2024-08-13T16:12:51.374142+00:00' AIRFLOW_CTX_TRY_NUMBER='1' AIRFLOW_CTX_DAG_RUN_ID='manual__2024-08-13T16:12:51.374142+00:00'
[2024-08-13T16:12:55.935+0000] {create_new_data.py:36} INFO - sample_size : 302
[2024-08-13T16:12:56.937+0000] {taskinstance.py:2698} ERROR - Task failed with exception
Traceback (most recent call last):
  File "/home/airflow/.local/lib/python3.8/site-packages/airflow/models/taskinstance.py", line 433, in _execute_task
    result = execute_callable(context=context, **execute_callable_kwargs)
  File "/home/airflow/.local/lib/python3.8/site-packages/airflow/operators/python.py", line 199, in execute
    return_value = self.execute_callable()
  File "/home/airflow/.local/lib/python3.8/site-packages/airflow/operators/python.py", line 216, in execute_callable
    return self.python_callable(*self.op_args, **self.op_kwargs)
  File "/opt/airflow/dags/create_new_data.py", line 42, in create_new_data
    df_train_new = pd.concat([df_train_new, sampled_df_stock], ignore_index=True)
UnboundLocalError: local variable 'df_train_new' referenced before assignment
[2024-08-13T16:12:56.969+0000] {taskinstance.py:1138} INFO - Marking task as FAILED. dag_id=create_new_data, task_id=create_new_data_task, execution_date=20240813T161251, start_date=20240813T161255, end_date=20240813T161256
[2024-08-13T16:12:57.012+0000] {standard_task_runner.py:107} ERROR - Failed to execute job 6 for task create_new_data_task (local variable 'df_train_new' referenced before assignment; 851)
[2024-08-13T16:12:57.056+0000] {local_task_job_runner.py:234} INFO - Task exited with return code 1
[2024-08-13T16:12:57.098+0000] {taskinstance.py:3280} INFO - 0 downstream tasks scheduled from follow-on schedule check
