[2024-08-16T16:45:20.042+0000] {scheduler_job_runner.py:781} ERROR - Executor reports task instance <TaskInstance: update_data_after_retrain.update_data_after_retrain manual__2024-08-16T16:45:18.879229+00:00 [queued]> finished (failed) although the task says it's queued. (Info: None) Was the task killed externally?
