[2024-09-07T13:21:17.987+0000] {taskinstance.py:1956} INFO - Dependencies all met for dep_context=non-requeueable deps ti=<TaskInstance: update_data_after_retrain.update_data_after_retrain manual__2024-09-07T13:21:09.062641+00:00 [queued]>
[2024-09-07T13:21:18.098+0000] {taskinstance.py:1956} INFO - Dependencies all met for dep_context=requeueable deps ti=<TaskInstance: update_data_after_retrain.update_data_after_retrain manual__2024-09-07T13:21:09.062641+00:00 [queued]>
[2024-09-07T13:21:18.099+0000] {taskinstance.py:2170} INFO - Starting attempt 1 of 1
[2024-09-07T13:21:18.172+0000] {taskinstance.py:2191} INFO - Executing <Task(PythonOperator): update_data_after_retrain> on 2024-09-07 13:21:09.062641+00:00
[2024-09-07T13:21:18.220+0000] {standard_task_runner.py:87} INFO - Running: ['***', 'tasks', 'run', 'update_data_after_retrain', 'update_data_after_retrain', 'manual__2024-09-07T13:21:09.062641+00:00', '--job-id', '75', '--raw', '--subdir', 'DAGS_FOLDER/update_data_after_retrain.py', '--cfg-path', '/tmp/tmph0qf48pd']
[2024-09-07T13:21:18.224+0000] {standard_task_runner.py:88} INFO - Job 75: Subtask update_data_after_retrain
[2024-09-07T13:21:18.191+0000] {standard_task_runner.py:60} INFO - Started process 1291 to run task
[2024-09-07T13:21:18.574+0000] {warnings.py:109} WARNING - /home/***/.local/lib/python3.8/site-packages/***/settings.py:194: DeprecationWarning: The sql_alchemy_conn option in [core] has been moved to the sql_alchemy_conn option in [database] - the old setting has been used, but please update your config.
  SQL_ALCHEMY_CONN = conf.get("database", "SQL_ALCHEMY_CONN")

[2024-09-07T13:21:19.299+0000] {task_command.py:423} INFO - Running <TaskInstance: update_data_after_retrain.update_data_after_retrain manual__2024-09-07T13:21:09.062641+00:00 [running]> on host 74653e659746
[2024-09-07T13:21:20.652+0000] {taskinstance.py:2480} INFO - Exporting env vars: AIRFLOW_CTX_DAG_OWNER='***' AIRFLOW_CTX_DAG_ID='update_data_after_retrain' AIRFLOW_CTX_TASK_ID='update_data_after_retrain' AIRFLOW_CTX_EXECUTION_DATE='2024-09-07T13:21:09.062641+00:00' AIRFLOW_CTX_TRY_NUMBER='1' AIRFLOW_CTX_DAG_RUN_ID='manual__2024-09-07T13:21:09.062641+00:00'
[2024-09-07T13:21:20.728+0000] {base.py:83} INFO - Using connection ID 'aws_default' for task execution.
[2024-09-07T13:21:20.731+0000] {connection_wrapper.py:378} INFO - AWS Connection (conn_id='aws_default', conn_type='aws') credentials retrieved from login and password.
[2024-09-07T13:21:21.633+0000] {taskinstance.py:2698} ERROR - Task failed with exception
Traceback (most recent call last):
  File "/home/airflow/.local/lib/python3.8/site-packages/airflow/models/taskinstance.py", line 433, in _execute_task
    result = execute_callable(context=context, **execute_callable_kwargs)
  File "/home/airflow/.local/lib/python3.8/site-packages/airflow/operators/python.py", line 199, in execute
    return_value = self.execute_callable()
  File "/home/airflow/.local/lib/python3.8/site-packages/airflow/operators/python.py", line 216, in execute_callable
    return self.python_callable(*self.op_args, **self.op_kwargs)
  File "/opt/airflow/dags/update_data_after_retrain.py", line 37, in update_data_after_retrain
    s3_hook.get_key(
TypeError: object_download_file() got an unexpected keyword argument 'local_file_path'
[2024-09-07T13:21:21.668+0000] {taskinstance.py:1138} INFO - Marking task as FAILED. dag_id=update_data_after_retrain, task_id=update_data_after_retrain, execution_date=20240907T132109, start_date=20240907T132118, end_date=20240907T132121
[2024-09-07T13:21:21.751+0000] {standard_task_runner.py:107} ERROR - Failed to execute job 75 for task update_data_after_retrain (object_download_file() got an unexpected keyword argument 'local_file_path'; 1291)
[2024-09-07T13:21:21.822+0000] {local_task_job_runner.py:234} INFO - Task exited with return code 1
[2024-09-07T13:21:21.904+0000] {taskinstance.py:3280} INFO - 0 downstream tasks scheduled from follow-on schedule check
