[2024-08-17T09:48:29.168+0000] {taskinstance.py:1956} INFO - Dependencies all met for dep_context=non-requeueable deps ti=<TaskInstance: new_data_management.send2bucket manual__2024-08-17T09:47:13.878248+00:00 [queued]>
[2024-08-17T09:48:29.221+0000] {taskinstance.py:1956} INFO - Dependencies all met for dep_context=requeueable deps ti=<TaskInstance: new_data_management.send2bucket manual__2024-08-17T09:47:13.878248+00:00 [queued]>
[2024-08-17T09:48:29.235+0000] {taskinstance.py:2170} INFO - Starting attempt 1 of 1
[2024-08-17T09:48:29.315+0000] {taskinstance.py:2191} INFO - Executing <Task(PythonOperator): send2bucket> on 2024-08-17 09:47:13.878248+00:00
[2024-08-17T09:48:29.338+0000] {standard_task_runner.py:60} INFO - Started process 31728 to run task
[2024-08-17T09:48:29.369+0000] {standard_task_runner.py:87} INFO - Running: ['***', 'tasks', 'run', 'new_data_management', 'send2bucket', 'manual__2024-08-17T09:47:13.878248+00:00', '--job-id', '54', '--raw', '--subdir', 'DAGS_FOLDER/new_data_management.py', '--cfg-path', '/tmp/tmp6ea9anns']
[2024-08-17T09:48:29.372+0000] {standard_task_runner.py:88} INFO - Job 54: Subtask send2bucket
[2024-08-17T09:48:29.442+0000] {warnings.py:109} WARNING - /home/***/.local/lib/python3.8/site-packages/***/settings.py:194: DeprecationWarning: The sql_alchemy_conn option in [core] has been moved to the sql_alchemy_conn option in [database] - the old setting has been used, but please update your config.
  SQL_ALCHEMY_CONN = conf.get("database", "SQL_ALCHEMY_CONN")

[2024-08-17T09:48:29.584+0000] {task_command.py:423} INFO - Running <TaskInstance: new_data_management.send2bucket manual__2024-08-17T09:47:13.878248+00:00 [running]> on host f23221e116fc
[2024-08-17T09:48:30.153+0000] {taskinstance.py:2480} INFO - Exporting env vars: AIRFLOW_CTX_DAG_OWNER='***' AIRFLOW_CTX_DAG_ID='new_data_management' AIRFLOW_CTX_TASK_ID='send2bucket' AIRFLOW_CTX_EXECUTION_DATE='2024-08-17T09:47:13.878248+00:00' AIRFLOW_CTX_TRY_NUMBER='1' AIRFLOW_CTX_DAG_RUN_ID='manual__2024-08-17T09:47:13.878248+00:00'
[2024-08-17T09:48:30.337+0000] {logging_mixin.py:188} INFO - retrain: False
[2024-08-17T09:48:30.340+0000] {new_data_management.py:121} INFO - retrain value from task 4 : False
[2024-08-17T09:48:30.341+0000] {python.py:201} INFO - Done. Returned value was: None
[2024-08-17T09:48:30.437+0000] {taskinstance.py:1138} INFO - Marking task as SUCCESS. dag_id=new_data_management, task_id=send2bucket, execution_date=20240817T094713, start_date=20240817T094829, end_date=20240817T094830
[2024-08-17T09:48:30.535+0000] {local_task_job_runner.py:234} INFO - Task exited with return code 0
[2024-08-17T09:48:30.676+0000] {taskinstance.py:3280} INFO - 0 downstream tasks scheduled from follow-on schedule check
