[2024-08-17T09:53:35.255+0000] {taskinstance.py:1956} INFO - Dependencies all met for dep_context=non-requeueable deps ti=<TaskInstance: update_data_after_retrain.update_data_after_retrain manual__2024-08-17T09:53:19.572784+00:00 [queued]>
[2024-08-17T09:53:35.321+0000] {taskinstance.py:1956} INFO - Dependencies all met for dep_context=requeueable deps ti=<TaskInstance: update_data_after_retrain.update_data_after_retrain manual__2024-08-17T09:53:19.572784+00:00 [queued]>
[2024-08-17T09:53:35.321+0000] {taskinstance.py:2170} INFO - Starting attempt 1 of 1
[2024-08-17T09:53:35.432+0000] {taskinstance.py:2191} INFO - Executing <Task(PythonOperator): update_data_after_retrain> on 2024-08-17 09:53:19.572784+00:00
[2024-08-17T09:53:35.454+0000] {standard_task_runner.py:60} INFO - Started process 31870 to run task
[2024-08-17T09:53:35.469+0000] {standard_task_runner.py:87} INFO - Running: ['***', 'tasks', 'run', 'update_data_after_retrain', 'update_data_after_retrain', 'manual__2024-08-17T09:53:19.572784+00:00', '--job-id', '59', '--raw', '--subdir', 'DAGS_FOLDER/update_data_after_retrain.py', '--cfg-path', '/tmp/tmpik38jyk6']
[2024-08-17T09:53:35.473+0000] {standard_task_runner.py:88} INFO - Job 59: Subtask update_data_after_retrain
[2024-08-17T09:53:35.588+0000] {warnings.py:109} WARNING - /home/***/.local/lib/python3.8/site-packages/***/settings.py:194: DeprecationWarning: The sql_alchemy_conn option in [core] has been moved to the sql_alchemy_conn option in [database] - the old setting has been used, but please update your config.
  SQL_ALCHEMY_CONN = conf.get("database", "SQL_ALCHEMY_CONN")

[2024-08-17T09:53:35.785+0000] {task_command.py:423} INFO - Running <TaskInstance: update_data_after_retrain.update_data_after_retrain manual__2024-08-17T09:53:19.572784+00:00 [running]> on host f23221e116fc
[2024-08-17T09:53:36.247+0000] {taskinstance.py:2480} INFO - Exporting env vars: AIRFLOW_CTX_DAG_OWNER='***' AIRFLOW_CTX_DAG_ID='update_data_after_retrain' AIRFLOW_CTX_TASK_ID='update_data_after_retrain' AIRFLOW_CTX_EXECUTION_DATE='2024-08-17T09:53:19.572784+00:00' AIRFLOW_CTX_TRY_NUMBER='1' AIRFLOW_CTX_DAG_RUN_ID='manual__2024-08-17T09:53:19.572784+00:00'
[2024-08-17T09:53:36.264+0000] {s3.py:1375} INFO - This function shadows the 'download_file' method of S3 API, but it is not the same. If you want to use the original method from S3 API, please call 'S3Hook.get_conn().download_file()'
[2024-08-17T09:53:36.265+0000] {s3.py:1381} INFO - Downloading source S3 file from Bucket my-karma-bucket with path train_model_metadata.json
[2024-08-17T09:53:36.319+0000] {base.py:83} INFO - Using connection ID 'aws_default' for task execution.
[2024-08-17T09:53:36.320+0000] {connection_wrapper.py:378} INFO - AWS Connection (conn_id='aws_default', conn_type='aws') credentials retrieved from login and password.
[2024-08-17T09:53:41.241+0000] {taskinstance.py:2698} ERROR - Task failed with exception
Traceback (most recent call last):
  File "/home/airflow/.local/lib/python3.8/site-packages/airflow/models/taskinstance.py", line 433, in _execute_task
    result = execute_callable(context=context, **execute_callable_kwargs)
  File "/home/airflow/.local/lib/python3.8/site-packages/airflow/operators/python.py", line 199, in execute
    return_value = self.execute_callable()
  File "/home/airflow/.local/lib/python3.8/site-packages/airflow/operators/python.py", line 216, in execute_callable
    return self.python_callable(*self.op_args, **self.op_kwargs)
  File "/opt/airflow/dags/update_data_after_retrain.py", line 37, in update_data_after_retrain
    s3_hook.download_file(
  File "/home/airflow/.local/lib/python3.8/site-packages/airflow/providers/amazon/aws/hooks/s3.py", line 137, in wrapper
    return func(*bound_args.args, **bound_args.kwargs)
  File "/home/airflow/.local/lib/python3.8/site-packages/airflow/providers/amazon/aws/hooks/s3.py", line 91, in wrapper
    return func(*bound_args.args, **bound_args.kwargs)
  File "/home/airflow/.local/lib/python3.8/site-packages/airflow/providers/amazon/aws/hooks/s3.py", line 1407, in download_file
    file = NamedTemporaryFile(dir=local_path, prefix="airflow_tmp_", delete=False)  # type: ignore
  File "/usr/local/lib/python3.8/tempfile.py", line 540, in NamedTemporaryFile
    (fd, name) = _mkstemp_inner(dir, prefix, suffix, flags, output_type)
  File "/usr/local/lib/python3.8/tempfile.py", line 250, in _mkstemp_inner
    fd = _os.open(file, flags, 0o600)
NotADirectoryError: [Errno 20] Not a directory: '/app/shared_volume/data/train_model_metadata.json/airflow_tmp_1ku5xnyn'
[2024-08-17T09:53:41.480+0000] {taskinstance.py:1138} INFO - Marking task as FAILED. dag_id=update_data_after_retrain, task_id=update_data_after_retrain, execution_date=20240817T095319, start_date=20240817T095335, end_date=20240817T095341
[2024-08-17T09:53:41.774+0000] {standard_task_runner.py:107} ERROR - Failed to execute job 59 for task update_data_after_retrain ([Errno 20] Not a directory: '/app/shared_volume/data/train_model_metadata.json/airflow_tmp_1ku5xnyn'; 31870)
[2024-08-17T09:53:41.985+0000] {local_task_job_runner.py:234} INFO - Task exited with return code 1
[2024-08-17T09:53:42.244+0000] {taskinstance.py:3280} INFO - 0 downstream tasks scheduled from follow-on schedule check
